<?xml version="1.0" encoding="utf-8"?>
<!-- This URDF was automatically created by SolidWorks to URDF Exporter! Originally created by Stephen Brawner (brawner@gmail.com) 
     Commit Version: 1.6.0-4-g7f85cfe  Build Version: 1.6.7995.38578
     For more information, please see http://wiki.ros.org/sw_urdf_exporter -->
<robot
  name="manipulator">
  <!-- Define the Dummy Link -->
<link name="link_dummy">
    <visual>
        <origin xyz="0 0 0" rpy="0 0 0" />
        <geometry>
            <box size="0.01 0.01 0.01" /> <!-- Use a small box for visualization -->
        </geometry>
        <material name="">
            <color rgba="1 0 0 1" /> <!-- Red color for visibility -->
        </material>
    </visual>
</link>

<!-- Add a Joint to Connect the Dummy Link to the Base Link -->
<joint name="joint_base_dummy" type="fixed">
    <origin xyz="0 0 0" rpy="0 0 0" /> <!-- Adjust this position as necessary -->
    <parent link="base_link" />
    <child link="link_dummy" />
</joint>
  <link
    name="base_link">
    <inertial>
      <origin
        xyz="0.110164377946591 -0.0894344248139039 -0.000559782561365218"
        rpy="0 0 0" />
      <mass
        value="0.0945948697764257" />
      <inertia
        ixx="0.000133072632825275"
        ixy="-8.08880087726543E-06"
        ixz="-1.55265839554671E-05"
        iyy="0.000145570115020265"
        iyz="2.47640864412752E-05"
        izz="0.000190687293495923" />
    </inertial>
    <visual>
      <origin
        xyz="0 0 0"
        rpy="0 0 0" />
      <geometry>
        <mesh
          filename="package://manipulator/meshes/base_link.STL" />
      </geometry>
      <material
        name="">
        <color
          rgba="0.627450980392157 0.627450980392157 0.627450980392157 1" />
      </material>
    </visual>
    <collision>
      <origin
        xyz="0 0 0"
        rpy="0 0 0" />
      <geometry>
        <mesh
          filename="package://manipulator/meshes/base_link.STL" />
      </geometry>
    </collision>
  </link>
  <link
    name="link_waist">
    <inertial>
      <origin
        xyz="0.00749462200181671 -0.00280637127097094 -0.00142932969864078"
        rpy="0 0 0" />
      <mass
        value="0.0736482065125356" />
      <inertia
        ixx="6.7954856684254E-05"
        ixy="-6.43019711406122E-06"
        ixz="2.545337426457E-07"
        iyy="6.0133991441919E-05"
        iyz="6.73122742415124E-06"
        izz="5.02832256418592E-05" />
    </inertial>
    <visual>
      <origin
        xyz="0 0 0"
        rpy="0 0 0" />
      <geometry>
        <mesh
          filename="package://manipulator/meshes/link_waist.STL" />
      </geometry>
      <material
        name="">
        <color
          rgba="0.627450980392157 0.627450980392157 0.627450980392157 1" />
      </material>
    </visual>
    <collision>
      <origin
        xyz="0 0 0"
        rpy="0 0 0" />
      <geometry>
        <mesh
          filename="package://manipulator/meshes/link_waist.STL" />
      </geometry>
    </collision>
  </link>
  <joint
    name="joint_base_waist"
    type="continuous">
    <origin
      xyz="0.100478709174496 -0.0656562967351186 0.0509945925861506"
      rpy="1.86216248284797 -0.368573868525035 -1.83635830754677" />
    <parent
      link="base_link" />
    <child
      link="link_waist" />
    <axis
      xyz="0 1 0" />
  </joint>
  <link
    name="link_arm01">
    <inertial>
      <origin
        xyz="0.00129272906852571 0.0599847631903156 -0.00497131817580272"
        rpy="0 0 0" />
      <mass
        value="0.0640544606432968" />
      <inertia
        ixx="0.000103706799533015"
        ixy="-2.03571258744201E-06"
        ixz="-2.46586877518744E-11"
        iyy="9.2726763879552E-06"
        iyz="4.56160416121703E-10"
        izz="0.000108619449047465" />
    </inertial>
    <visual>
      <origin
        xyz="0 0 0"
        rpy="0 0 0" />
      <geometry>
        <mesh
          filename="package://manipulator/meshes/link_arm01.STL" />
      </geometry>
      <material
        name="">
        <color
          rgba="0.627450980392157 0.627450980392157 0.627450980392157 1" />
      </material>
    </visual>
    <collision>
      <origin
        xyz="0 0 0"
        rpy="0 0 0" />
      <geometry>
        <mesh
          filename="package://manipulator/meshes/link_arm01.STL" />
      </geometry>
    </collision>
  </link>
  <joint
    name="joint_waist_arm01"
    type="continuous">
    <origin
      xyz="0 0.018090375352197 -0.0139100000000071"
      rpy="1.5707963267946 1.10898105062242 1.57079632679463" />
    <parent
      link="link_waist" />
    <child
      link="link_arm01" />
    <axis
      xyz="0 0 1" />
  </joint>
  <link
    name="link_arm02">
    <inertial>
      <origin
        xyz="0.0427311796584287 -0.00240751880131511 0.00971993709487167"
        rpy="0 0 0" />
      <mass
        value="0.0470979601767716" />
      <inertia
        ixx="8.72266112071269E-06"
        ixy="6.96875924353953E-08"
        ixz="4.03568961614107E-07"
        iyy="5.14006986895581E-05"
        iyz="-1.82397415895724E-10"
        izz="5.46642509743615E-05" />
    </inertial>
    <visual>
      <origin
        xyz="0 0 0"
        rpy="0 0 0" />
      <geometry>
        <mesh
          filename="package://manipulator/meshes/link_arm02.STL" />
      </geometry>
      <material
        name="">
        <color
          rgba="0.627450980392157 0.627450980392157 0.627450980392157 1" />
      </material>
    </visual>
    <collision>
      <origin
        xyz="0 0 0"
        rpy="0 0 0" />
      <geometry>
        <mesh
          filename="package://manipulator/meshes/link_arm02.STL" />
      </geometry>
    </collision>
  </link>
  <joint
    name="joint_arm01_arm02"
    type="continuous">
    <origin
      xyz="0 0.120000000000003 0"
      rpy="0 0 1.1544064242663" />
    <parent
      link="link_arm01" />
    <child
      link="link_arm02" />
    <axis
      xyz="0 0 1" />
  </joint>
  <link
    name="link_arm03">
    <inertial>
      <origin
        xyz="0.00638326841687217 0.00660943464186645 -0.0068996816068671"
        rpy="0 0 0" />
      <mass
        value="0.0164704027054544" />
      <inertia
        ixx="3.91574170614055E-06"
        ixy="-5.56474545952712E-08"
        ixz="-1.31895382131963E-07"
        iyy="2.60897723184576E-06"
        iyz="5.74580421631354E-07"
        izz="4.99187852065969E-06" />
    </inertial>
    <visual>
      <origin
        xyz="0 0 0"
        rpy="0 0 0" />
      <geometry>
        <mesh
          filename="package://manipulator/meshes/link_arm03.STL" />
      </geometry>
      <material
        name="">
        <color
          rgba="0.627450980392157 0.627450980392157 0.627450980392157 1" />
      </material>
    </visual>
    <collision>
      <origin
        xyz="0 0 0"
        rpy="0 0 0" />
      <geometry>
        <mesh
          filename="package://manipulator/meshes/link_arm03.STL" />
      </geometry>
    </collision>
  </link>
  <joint
    name="joint_arm02_arm03"
    type="continuous">
    <origin
      xyz="0.103168801289468 0.00530000000121461 0.00949999999992188"
      rpy="0 -1.24589601241689 -1.57079632682694" />
    <parent
      link="link_arm02" />
    <child
      link="link_arm03" />
    <axis
      xyz="0 1 0" />
  </joint>
  <link
    name="link_gripper_wrist">
    <inertial>
      <origin
        xyz="-0.0142109632990201 0.0156055264158059 0.0216496658055875"
        rpy="0 0 0" />
      <mass
        value="0.0160406410244945" />
      <inertia
        ixx="7.56234515895802E-06"
        ixy="-1.80514351076937E-07"
        ixz="-1.40597452139778E-06"
        iyy="9.04534964188705E-06"
        iyz="-1.27228630302088E-06"
        izz="2.9591422289527E-06" />
    </inertial>
    <visual>
      <origin
        xyz="0 0 0"
        rpy="0 0 0" />
      <geometry>
        <mesh
          filename="package://manipulator/meshes/link_gripper_wrist.STL" />
      </geometry>
      <material
        name="">
        <color
          rgba="0.498039215686275 0.498039215686275 0.498039215686275 1" />
      </material>
    </visual>
    <collision>
      <origin
        xyz="0 0 0"
        rpy="0 0 0" />
      <geometry>
        <mesh
          filename="package://manipulator/meshes/link_gripper_wrist.STL" />
      </geometry>
    </collision>
  </link>
  <joint
    name="joint_arm03_gripper"
    type="continuous">
    <origin
      xyz="0 0.01 0"
      rpy="3.09077521367807 -1.57079631189374 2.73120362922848" />
    <parent
      link="link_arm03" />
    <child
      link="link_gripper_wrist" />
    <axis
      xyz="1 0 0" />
  </joint>
  <link
    name="link_gear_motor">
    <inertial>
      <origin
        xyz="0.04463261905914 -0.00814483018706101 -0.018176468029334"
        rpy="0 0 0" />
      <mass
        value="0.00258180823330291" />
      <inertia
        ixx="9.00151478960092E-08"
        ixy="8.33723130309093E-09"
        ixz="-9.0638315620498E-22"
        iyy="3.68688286362483E-07"
        iyz="5.10784028251495E-23"
        izz="4.51818612303018E-07" />
    </inertial>
    <visual>
      <origin
        xyz="0 0 0"
        rpy="0 0 0" />
      <geometry>
        <mesh
          filename="package://manipulator/meshes/link_gear_motor.STL" />
      </geometry>
      <material
        name="">
        <color
          rgba="0.627450980392157 0.627450980392157 0.627450980392157 1" />
      </material>
    </visual>
    <collision>
      <origin
        xyz="0 0 0"
        rpy="0 0 0" />
      <geometry>
        <mesh
          filename="package://manipulator/meshes/link_gear_motor.STL" />
      </geometry>
    </collision>
  </link>
  <joint
    name="joint_wrist_gear_motor"
    type="continuous">
    <origin
      xyz="-0.0151308298057989 0.00740230118402704 -0.00190478098708853"
      rpy="1.62193314321017 -1.46493424551406 -0.102365080176138" />
    <parent
      link="link_gripper_wrist" />
    <child
      link="link_gear_motor" />
    <axis
      xyz="0.208554590258567 -0.978010727385994 0" />
  </joint>
  <link
    name="link_finger_motor">
    <inertial>
      <origin
        xyz="0.0784813054779672 0.0117499986657535 -0.0525413794587481"
        rpy="0 0 0" />
      <mass
        value="0.00255464559787999" />
      <inertia
        ixx="6.09412019691677E-08"
        ixy="-2.62800540051186E-13"
        ixz="1.55267808871726E-07"
        iyy="8.10460658621149E-07"
        iyz="-5.24793927349687E-15"
        izz="7.58141519921509E-07" />
    </inertial>
    <visual>
      <origin
        xyz="0 0 0"
        rpy="0 0 0" />
      <geometry>
        <mesh
          filename="package://manipulator/meshes/link_finger_motor.STL" />
      </geometry>
      <material
        name="">
        <color
          rgba="0.627450980392157 0.627450980392157 0.627450980392157 1" />
      </material>
    </visual>
    <collision>
      <origin
        xyz="0 0 0"
        rpy="0 0 0" />
      <geometry>
        <mesh
          filename="package://manipulator/meshes/link_finger_motor.STL" />
      </geometry>
    </collision>
  </link>
  <joint
    name="joint_gear_motor_finger"
    type="continuous">
    <origin
      xyz="-0.00180406326351987 0.000798239901647332 -0.00192646802933377"
      rpy="-1.5707963267949 0 0.616208531093524" />
    <parent
      link="link_gear_motor" />
    <child
      link="link_finger_motor" />
    <axis
      xyz="0.39504029447576 0 0.918663793637533" />
  </joint>
  <link
    name="link_support_motor">
    <inertial>
      <origin
        xyz="0.0722080886563065 0.0181507111127688 0.0049394584617492"
        rpy="0 0 0" />
      <mass
        value="0.000798762413184691" />
      <inertia
        ixx="3.6325042236301E-09"
        ixy="4.24834792728407E-23"
        ixz="-7.51700381657564E-23"
        iyy="1.04424225659603E-07"
        iyz="-1.03397576569128E-25"
        izz="1.02921754537799E-07" />
    </inertial>
    <visual>
      <origin
        xyz="0 0 0"
        rpy="0 0 0" />
      <geometry>
        <mesh
          filename="package://manipulator/meshes/link_support_motor.STL" />
      </geometry>
      <material
        name="">
        <color
          rgba="0.627450980392157 0.627450980392157 0.627450980392157 1" />
      </material>
    </visual>
    <collision>
      <origin
        xyz="0 0 0"
        rpy="0 0 0" />
      <geometry>
        <mesh
          filename="package://manipulator/meshes/link_support_motor.STL" />
      </geometry>
    </collision>
  </link>
  <joint
    name="joint_gear_motor_support"
    type="continuous">
    <origin
      xyz="5.25790110262811E-05 -0.000496779214404539 -2.57569164497928E-05"
      rpy="-1.5707963267949 0 -0.00518044088048919" />
    <parent
      link="link_gear_motor" />
    <child
      link="link_support_motor" />
    <axis
      xyz="0.213618295870458 0 -0.976917204101454" />
  </joint>
  <link
    name="link_gear_non_motor">
    <inertial>
      <origin
        xyz="0.0443460144739399 -0.00850842807968651 0.0162499999999518"
        rpy="0 0 0" />
      <mass
        value="0.00265818035071166" />
      <inertia
        ixx="9.02347898780712E-08"
        ixy="8.09769450575749E-09"
        ixz="-8.35452418678558E-23"
        iyy="3.7202878646128E-07"
        iyz="-8.63369764352223E-23"
        izz="4.5517509540412E-07" />
    </inertial>
    <visual>
      <origin
        xyz="0 0 0"
        rpy="0 0 0" />
      <geometry>
        <mesh
          filename="package://manipulator/meshes/link_gear_non_motor.STL" />
      </geometry>
      <material
        name="">
        <color
          rgba="0.627450980392157 0.627450980392157 0.627450980392157 1" />
      </material>
    </visual>
    <collision>
      <origin
        xyz="0 0 0"
        rpy="0 0 0" />
      <geometry>
        <mesh
          filename="package://manipulator/meshes/link_gear_non_motor.STL" />
      </geometry>
    </collision>
  </link>
  <joint
    name="joint_wrist_gear_non_motor"
    type="continuous">
    <origin
      xyz="-0.0126144790147938 0.00920887596041156 -0.00324751562511042"
      rpy="1.54262490601649 -1.37785740063633 3.11772758003403" />
    <parent
      link="link_gripper_wrist" />
    <child
      link="link_gear_non_motor" />
    <axis
      xyz="0.0883767144837315 -0.996087122864793 0" />
  </joint>
  <link
    name="link_finger_non_motor">
    <inertial>
      <origin
        xyz="0.0777112087653918 -0.0117500038825281 -0.0541256028723106"
        rpy="0 0 0" />
      <mass
        value="0.00255464600150248" />
      <inertia
        ixx="6.09413937448075E-08"
        ixy="-1.84322826805609E-13"
        ixz="1.55267857454146E-07"
        iyy="8.10460608174776E-07"
        iyz="3.07285306193079E-14"
        izz="7.58141278556825E-07" />
    </inertial>
    <visual>
      <origin
        xyz="0 0 0"
        rpy="0 0 0" />
      <geometry>
        <mesh
          filename="package://manipulator/meshes/link_finger_non_motor.STL" />
      </geometry>
      <material
        name="">
        <color
          rgba="0.627450980392157 0.627450980392157 0.627450980392157 1" />
      </material>
    </visual>
    <collision>
      <origin
        xyz="0 0 0"
        rpy="0 0 0" />
      <geometry>
        <mesh
          filename="package://manipulator/meshes/link_finger_non_motor.STL" />
      </geometry>
    </collision>
  </link>
  <joint
    name="joint_gear_non_motor_finger"
    type="continuous">
    <origin
      xyz="-0.000131735077104032 0.0114847758791033 0"
      rpy="-1.5707963267949 0 0.485250499592955" />
    <parent
      link="link_gear_non_motor" />
    <child
      link="link_finger_non_motor" />
    <axis
      xyz="0.386430530565165 0 0.92231851604916" />
  </joint>
  <link
    name="link_support_non_motor">
    <inertial>
      <origin
        xyz="-0.0720036700548316 0.018150711112734 0.00133115482133332"
        rpy="0 0 0" />
      <mass
        value="0.000798762413184689" />
      <inertia
        ixx="3.63250422363008E-09"
        ixy="-1.21207809133161E-22"
        ixz="1.2187989338086E-23"
        iyy="1.04424225659603E-07"
        iyz="1.72221588472955E-24"
        izz="1.02921754537799E-07" />
    </inertial>
    <visual>
      <origin
        xyz="0 0 0"
        rpy="0 0 0" />
      <geometry>
        <mesh
          filename="package://manipulator/meshes/link_support_non_motor.STL" />
      </geometry>
      <material
        name="">
        <color
          rgba="0.627450980392157 0.627450980392157 0.627450980392157 1" />
      </material>
    </visual>
    <collision>
      <origin
        xyz="0 0 0"
        rpy="0 0 0" />
      <geometry>
        <mesh
          filename="package://manipulator/meshes/link_support_non_motor.STL" />
      </geometry>
    </collision>
  </link>
  <joint
    name="joint_gear_non_motor_support"
    type="continuous">
    <origin
      xyz="0.00169602614000509 -0.0016254951164789 -0.00190071111288237"
      rpy="1.57079632679491 0 -3.12464901226904" />
    <parent
      link="link_gear_non_motor" />
    <child
      link="link_support_non_motor" />
    <axis
      xyz="0.0714874934825342 0 0.99744149616686" />
  </joint>
</robot>