<?xml version="1.0" encoding="utf-8"?>
<!-- This URDF was automatically created by SolidWorks to URDF Exporter! Originally created by Stephen Brawner (brawner@gmail.com) 
     Commit Version: 1.6.0-4-g7f85cfe  Build Version: 1.6.7995.38578
     For more information, please see http://wiki.ros.org/sw_urdf_exporter -->
<robot
  name="manipulator">
  <link name="world">
    <visual>
        <origin xyz="-0.014790 0.274300 0.079552" rpy="-0.125191 0.448281 -1.594174" />
        <geometry>
            <box size="0.01 0.01 0.01" /> <!-- Use a small box for visualization -->
        </geometry>
        <material name="">
            <color rgba="1 0 0 1" /> <!-- Red color for visibility -->
        </material>
    </visual>
</link>

<!-- Add a Joint to Connect the Dummy Link to the Base Link -->
<joint name="joint_world_base_link" type="fixed">
    <origin xyz="0 0 0.1" rpy="0.52 0.3 0" /> <!-- Adjust this position as necessary -->
    <parent link="world" />
    <child link="base_link" />
</joint>
  <link
    name="base_link">
    <inertial>
      <origin
        xyz="0.110164377946591 -0.0894344248139039 -0.000559782561365217"
        rpy="0 0 0" />
      <mass
        value="0.0945948697764257" />
      <inertia
        ixx="0.000133072632825275"
        ixy="-8.08880087726543E-06"
        ixz="-1.55265839554671E-05"
        iyy="0.000145570115020265"
        iyz="2.47640864412752E-05"
        izz="0.000190687293495923" />
    </inertial>
    <visual>
      <origin
        xyz="0 0 0"
        rpy="0 0 0" />
      <geometry>
        <mesh
          filename="package://manipulator/meshes/base_link.STL" />
      </geometry>
      <material
        name="">
        <color
          rgba="0.627450980392157 0.627450980392157 0.627450980392157 1" />
      </material>
    </visual>
    <collision>
      <origin
        xyz="0 0 0"
        rpy="0 0 0" />
      <geometry>
        <mesh
          filename="package://manipulator/meshes/base_link.STL" />
      </geometry>
    </collision>
  </link>
  <link
    name="link_waist">
    <inertial>
      <origin
        xyz="0.00749460466607962 0.0193833742805122 -0.00142908295604847"
        rpy="0 0 0" />
      <mass
        value="0.073648017160832" />
      <inertia
        ixx="6.79533649959477E-05"
        ixy="-6.43007186079431E-06"
        ixz="2.54253113515054E-07"
        iyy="6.01331618037357E-05"
        iyz="6.73058268215776E-06"
        izz="5.02824951550106E-05" />
    </inertial>
    <visual>
      <origin
        xyz="0 0 0"
        rpy="0 0 0" />
      <geometry>
        <mesh
          filename="package://manipulator/meshes/link_waist.STL" />
      </geometry>
      <material
        name="">
        <color
          rgba="0.627450980392157 0.627450980392157 0.627450980392157 1" />
      </material>
    </visual>
    <collision>
      <origin
        xyz="0 0 0"
        rpy="0 0 0" />
      <geometry>
        <mesh
          filename="package://manipulator/meshes/link_waist.STL" />
      </geometry>
    </collision>
  </link>
  <joint
    name="joint_base_waist"
    type="continuous">
    <origin
      xyz="0.104619716257001 -0.0747184271679116 0.0311676085902517"
      rpy="1.24263440323189 0.336564980145166 1.19877807114456" />
    <parent
      link="base_link" />
    <child
      link="link_waist" />
    <axis
      xyz="0 1 0" />
    <limit
      lower="0"
      upper="0"
      effort="338"
      velocity="10" />
        
  </joint>
  <link
    name="link_arm01">
    <inertial>
      <origin
        xyz="7.28828564999784E-08 0.0599999721913967 0.0132291412086"
        rpy="0 0 0" />
      <mass
        value="0.064057051230774" />
      <inertia
        ixx="0.000103753554172636"
        ixy="2.72460845131853E-10"
        ixz="1.08923157262337E-10"
        iyy="9.2284882991871E-06"
        iyz="-7.47048066025201E-11"
        izz="0.000108623418422058" />
    </inertial>
    <visual>
      <origin
        xyz="0 0 0"
        rpy="0 0 0" />
      <geometry>
        <mesh
          filename="package://manipulator/meshes/link_arm01.STL" />
      </geometry>
      <material
        name="">
        <color
          rgba="0.627450980392157 0.627450980392157 0.627450980392157 1" />
      </material>
    </visual>
    <collision>
      <origin
        xyz="0 0 0"
        rpy="0 0 0" />
      <geometry>
        <mesh
          filename="package://manipulator/meshes/link_arm01.STL" />
      </geometry>
    </collision>
  </link>
  <joint
    name="joint_waist_arm01"
    type="revolute">
    <origin
      xyz="-0.0182 0.0402799999999999 -0.0139099999999999"
      rpy="1.57079632679491 1.44053245288332 1.57079632679491" />
    <parent
      link="link_waist" />
    <child
      link="link_arm01" />
    <axis
      xyz="0 0 1" />
    <limit
      lower="-1.4"
      upper="1.4"
      effort="338"
      velocity="10" />
    <!-- <dynamics damping="0.2" friction="0.6"/> -->
  </joint>
  <link
    name="link_arm02">
    <inertial>
      <origin
        xyz="-0.000507747225750504 0.0417075716278682 -0.0129199551350853"
        rpy="0 0 0" />
      <mass
        value="0.0470979731232057" />
      <inertia
        ixx="5.13940350110077E-05"
        ixy="5.56792946865546E-07"
        ixz="4.79475725568015E-09"
        iyy="8.72979889935788E-06"
        iyz="-4.03667116053884E-07"
        izz="5.46647133889416E-05" />
    </inertial>
    <visual>
      <origin
        xyz="0 0 0"
        rpy="0 0 0" />
      <geometry>
        <mesh
          filename="package://manipulator/meshes/link_arm02.STL" />
      </geometry>
      <material
        name="">
        <color
          rgba="0.627450980392157 0.627450980392157 0.627450980392157 1" />
      </material>
    </visual>
    <collision>
      <origin
        xyz="0 0 0"
        rpy="0 0 0" />
      <geometry>
        <mesh
          filename="package://manipulator/meshes/link_arm02.STL" />
      </geometry>
    </collision>
  </link>
  <joint
    name="joint_arm01_arm02"
    type="revolute">
    <origin
      xyz="0 0.12 0.015"
      rpy="3.14159265358979 0 -2.94369460393837" />
    <parent
      link="link_arm01" />
    <child
      link="link_arm02" />
    <axis
      xyz="0 0 -1" />
    <limit
      lower="-1.4"
      upper="1.4"
      effort="338"
      velocity="10" />
  </joint>
  <link
    name="link_arm03">
    <inertial>
      <origin
        xyz="4.59621324966769E-05 0.0178079248857709 -0.00527093987895778"
        rpy="0 0 0" />
      <mass
        value="0.0164703704574985" />
      <inertia
        ixx="3.8998112272154E-06"
        ixy="1.15515572844753E-08"
        ixz="-3.9843285770846E-09"
        iyy="2.60896890580714E-06"
        iyz="5.77154659865444E-07"
        izz="5.00777358212754E-06" />
    </inertial>
    <visual>
      <origin
        xyz="0 0 0"
        rpy="0 0 0" />
      <geometry>
        <mesh
          filename="package://manipulator/meshes/link_arm03.STL" />
      </geometry>
      <material
        name="">
        <color
          rgba="0.627450980392157 0.627450980392157 0.627450980392157 1" />
      </material>
    </visual>
    <collision>
      <origin
        xyz="0 0 0"
        rpy="0 0 0" />
      <geometry>
        <mesh
          filename="package://manipulator/meshes/link_arm03.STL" />
      </geometry>
    </collision>
  </link>
  <joint
    name="joint_arm02_arm03"
    type="continuous">
    <origin
      xyz="-0.0001165850778517 0.090954594899946 -0.0151145368982072"
      rpy="3.14159265358979 0.503971856291605 -3.13017769589601" />
    <parent
      link="link_arm02" />
    <child
      link="link_arm03" />
    <axis
      xyz="0 -1 0" />
    <limit
      lower="-1.4"
      upper="1.4"
      effort="338"
      velocity="10" />
  </joint>
  <link
    name="link_wrist">
    <inertial>
      <origin
        xyz="0.0241387897424202 -0.00895517640972743 0.00515759512288279"
        rpy="0 0 0" />
      <mass
        value="0.0160406157199611" />
      <inertia
        ixx="3.6333607086399E-06"
        ixy="1.89318060885119E-06"
        ixz="-1.73518802637373E-06"
        iyy="8.67578848292488E-06"
        iyz="5.85402145999365E-07"
        izz="7.25768021095932E-06" />
    </inertial>
    <visual>
      <origin
        xyz="0 0 0"
        rpy="0 0 0" />
      <geometry>
        <mesh
          filename="package://manipulator/meshes/link_wrist.STL" />
      </geometry>
      <material
        name="">
        <color
          rgba="0.498039215686275 0.498039215686275 0.498039215686275 1" />
      </material>
    </visual>
    <collision>
      <origin
        xyz="0 0 0"
        rpy="0 0 0" />
      <geometry>
        <mesh
          filename="package://manipulator/meshes/link_wrist.STL" />
      </geometry>
    </collision>
  </link>
  <joint
    name="joint_arm03_wrist"
    type="revolute">
    <origin
      xyz="0 0.028 -0.0155"
      rpy="0 0 2.97515466965945" />
    <parent
      link="link_arm03" />
    <child
      link="link_wrist" />
    <axis
      xyz="0 0 -1" />
    <limit
      lower="-1.4"
      upper="1.4"
      effort="338"
      velocity="10" />
  </joint>
  <link
    name="link_servo">
    <inertial>
      <origin
        xyz="-0.000421588407400978 2.77555756156289E-17 0.0125976635534302"
        rpy="0 0 0" />
      <mass
        value="0.00717741212346476" />
      <inertia
        ixx="4.65659768608823E-07"
        ixy="3.4410713482206E-22"
        ixz="3.64468103975E-08"
        iyy="7.15747199073412E-07"
        iyz="-4.2351647362715E-22"
        izz="4.29370258276757E-07" />
    </inertial>
    <visual>
      <origin
        xyz="0 0 0"
        rpy="0 0 0" />
      <geometry>
        <mesh
          filename="package://manipulator/meshes/link_servo.STL" />
      </geometry>
      <material
        name="">
        <color
          rgba="0.627450980392157 0.627450980392157 0.627450980392157 1" />
      </material>
    </visual>
    <collision>
      <origin
        xyz="0 0 0"
        rpy="0 0 0" />
      <geometry>
        <mesh
          filename="package://manipulator/meshes/link_servo.STL" />
      </geometry>
    </collision>
  </link>
  <joint
    name="joint_wrist_servo_fixed"
    type="fixed">
    <origin
      xyz="0.0393088925164345 0.010787653550768 0.024"
      rpy="1.67321358298702 -1.5707963267949 0" />
    <parent
      link="link_wrist" />
    <child
      link="link_servo" />
    <axis
      xyz="0 0 0" />
  </joint>
  <link
    name="link_motor_gear">
    <inertial>
      <origin
        xyz="0.00498745739687451 0.00250589540319929 -1.66533453693773E-16"
        rpy="0 0 0" />
      <mass
        value="0.0025818082333029" />
      <inertia
        ixx="1.19303857754038E-07"
        ixy="-8.58700040667533E-08"
        ixz="4.32615460365233E-22"
        iyy="3.39399576504453E-07"
        iyz="2.11758236813575E-22"
        izz="4.51818612303017E-07" />
    </inertial>
    <visual>
      <origin
        xyz="0 0 0"
        rpy="0 0 0" />
      <geometry>
        <mesh
          filename="package://manipulator/meshes/link_motor_gear.STL" />
      </geometry>
      <material
        name="">
        <color
          rgba="0.627450980392157 0.627450980392157 0.627450980392157 1" />
      </material>
    </visual>
    <collision>
      <origin
        xyz="0 0 0"
        rpy="0 0 0" />
      <geometry>
        <mesh
          filename="package://manipulator/meshes/link_motor_gear.STL" />
      </geometry>
    </collision>
  </link>
  <joint
    name="joint_wrist_motor_gear"
    type="revolute">
    <origin
      xyz="0.0361395051353438 -0.0200499044528838 0.0189000000000357"
      rpy="-1.5707963267949 -0.852106499830379 -0.102417256192125" />
    <parent
      link="link_wrist" />
    <child
      link="link_motor_gear" />
    <axis
      xyz="0 0 -1" />
    <limit
      lower="-0.09"
      upper="0.0275"
      effort="338"
      velocity="10" />
  </joint>
  <link
    name="link_motor_finger">
    <inertial>
      <origin
        xyz="0.0110070406755422 -0.0232758678124116 -0.00250000291050845"
        rpy="0 0 0" />
      <mass
        value="0.00255464599773235" />
      <inertia
        ixx="6.02661453666928E-07"
        ixy="3.29142587048583E-07"
        ixz="-8.31957162243927E-14"
        iyy="2.16421662192353E-07"
        iyz="1.97906599030425E-13"
        izz="8.10461051433769E-07" />
    </inertial>
    <visual>
      <origin
        xyz="0 0 0"
        rpy="0 0 0" />
      <geometry>
        <mesh
          filename="package://manipulator/meshes/link_motor_finger.STL" />
      </geometry>
      <material
        name="">
        <color
          rgba="0.627450980392157 0.627450980392157 0.627450980392157 1" />
      </material>
    </visual>
    <collision>
      <origin
        xyz="0 0 0"
        rpy="0 0 0" />
      <geometry>
        <mesh
          filename="package://manipulator/meshes/link_motor_finger.STL" />
      </geometry>
    </collision>
  </link>
  <joint
    name="joint_motor_gear_finger"
    type="continuous">
    <origin
      xyz="0.028766 0.010867 0.002"
      rpy="3.1416 0 0" />
    <parent
      link="link_motor_gear" />
    <child
      link="link_motor_finger" />
    <axis
      xyz="0 0 -1" />
    <limit
      lower="-1.4"
      upper="1.4"
      effort="0"
      velocity="10" />
	<mimic joint="joint_wrist_motor_gear" multiplier="-0.8"/>
  </joint>
  <link
    name="link_non_motor_gear">
    <inertial>
      <origin
        xyz="0.00492502906299691 0.00226580338795912 -5.55111512312578E-17"
        rpy="0 0 0" />
      <mass
        value="0.00265818035071168" />
      <inertia
        ixx="1.14346304850681E-07"
        ixy="-7.92381705356815E-08"
        ixz="8.33798057453452E-22"
        iyy="3.47917271488674E-07"
        iyz="1.43102245971674E-22"
        izz="4.55175095404124E-07" />
    </inertial>
    <visual>
      <origin
        xyz="0 0 0"
        rpy="0 0 0" />
      <geometry>
        <mesh
          filename="package://manipulator/meshes/link_non_motor_gear.STL" />
      </geometry>
      <material
        name="">
        <color
          rgba="0.627450980392157 0.627450980392157 0.627450980392157 1" />
      </material>
    </visual>
    <collision>
      <origin
        xyz="0 0 0"
        rpy="0 0 0" />
      <geometry>
        <mesh
          filename="package://manipulator/meshes/link_non_motor_gear.STL" />
      </geometry>
    </collision>
  </link>
  <joint
    name="joint_wrist_non_motor_gear"
    type="revolute">
    <origin
      xyz="0.0361395051353807 -0.0200499044528875 -0.00800000000000281"
      rpy="1.5707963267949 0.696091483245096 -0.102417256192129" />
    <parent
      link="link_wrist" />
    <child
      link="link_non_motor_gear" />
    <axis
      xyz="0 0 1" />
    <limit
      lower="-1.4"
      upper="1.4"
      effort="0"
      velocity="10" />
<mimic joint="joint_wrist_motor_gear" multiplier="-1.0"/>
  </joint>
  <link
    name="link_non_motor_finger">
    <inertial>
      <origin
        xyz="0.0212959212969732 0.0144708261452938 0.00649999825189373"
        rpy="0 0 0" />
      <mass
        value="0.00255464579636163" />
      <inertia
        ixx="3.26118952390743E-07"
        ixy="-3.72385346632874E-07"
        ixz="-2.22677707980307E-13"
        iyy="4.92964020378245E-07"
        iyz="-1.13606576757357E-13"
        izz="8.10460908906223E-07" />
    </inertial>
    <visual>
      <origin
        xyz="0 0 0"
        rpy="0 0 0" />
      <geometry>
        <mesh
          filename="package://manipulator/meshes/link_non_motor_finger.STL" />
      </geometry>
      <material
        name="">
        <color
          rgba="0.627450980392157 0.627450980392157 0.627450980392157 1" />
      </material>
    </visual>
    <collision>
      <origin
        xyz="0 0 0"
        rpy="0 0 0" />
      <geometry>
        <mesh
          filename="package://manipulator/meshes/link_non_motor_finger.STL" />
      </geometry>
    </collision>
  </link>
  <joint
    name="joint_non_motor_gear_finger"
    type="revolute">
    <origin
      xyz="0.029123 0.0098705 0.002"
      rpy="-3.1416 0 1.5482" />
    <parent
      link="link_non_motor_gear" />
    <child
      link="link_non_motor_finger" />
    <axis
      xyz="0 0 -1" />
    <limit
      lower="-1.4"
      upper="1.4"
      effort="0"
      velocity="10" />
<mimic joint="joint_wrist_motor_gear" multiplier="-0.8"/>
  </joint>
  <link
    name="link_motor_support">
    <inertial>
      <origin
        xyz="0.0146933813542968 0.002 0.0049350323582818"
        rpy="0 0 0" />
      <mass
        value="0.000798762413184692" />
      <inertia
        ixx="1.36976216135713E-08"
        ixy="7.70828933322853E-23"
        ixz="-2.99675052665061E-08"
        iyy="1.04424225659604E-07"
        iyz="2.31610571514848E-23"
        izz="9.28566371478583E-08" />
    </inertial>
    <visual>
      <origin
        xyz="0 0 0"
        rpy="0 0 0" />
      <geometry>
        <mesh
          filename="package://manipulator/meshes/link_motor_support.STL" />
      </geometry>
      <material
        name="">
        <color
          rgba="0.627450980392157 0.627450980392157 0.627450980392157 1" />
      </material>
    </visual>
    <collision>
      <origin
        xyz="0 0 0"
        rpy="0 0 0" />
      <geometry>
        <mesh
          filename="package://manipulator/meshes/link_motor_support.STL" />
      </geometry>
    </collision>
  </link>
  <joint
    name="joint_wrist_motor_support"
    type="revolute">
    <origin
      xyz="0.0562391804526159 -0.0201051506339748 0.0100000000000436"
      rpy="-3.14159265358979 -0.81681166488745 -0.102417256192128" />
    <parent
      link="link_wrist" />
    <child
      link="link_motor_support" />
    <axis
      xyz="0 1 0" />
    <limit
      lower="-1.4"
      upper="1.4"
      effort="0"
      velocity="10" />
<mimic joint="joint_wrist_motor_gear" multiplier="1.2"/>
  </joint>
  <link
    name="link_non_motor_support">
    <inertial>
      <origin
        xyz="0.00549698307306112 0.0144925214194936 0.00199999999999989"
        rpy="0 0 0" />
      <mass
        value="0.000798762413184692" />
      <inertia
        ixx="9.04339056588605E-08"
        ixy="-3.29235900776828E-08"
        ixz="3.82571033305775E-24"
        iyy="1.61203531025693E-08"
        iyz="2.8951321439356E-23"
        izz="1.04424225659604E-07" />
    </inertial>
    <visual>
      <origin
        xyz="0 0 0"
        rpy="0 0 0" />
      <geometry>
        <mesh
          filename="package://manipulator/meshes/link_non_motor_support.STL" />
      </geometry>
      <material
        name="">
        <color
          rgba="0.627450980392157 0.627450980392157 0.627450980392157 1" />
      </material>
    </visual>
    <collision>
      <origin
        xyz="0 0 0"
        rpy="0 0 0" />
      <geometry>
        <mesh
          filename="package://manipulator/meshes/link_non_motor_support.STL" />
      </geometry>
    </collision>
  </link>
  <joint
    name="joint_wrist_non_motor_support"
    type="revolute">
    <origin
      xyz="0.0558302272421884 -0.0240841903763851 0"
      rpy="-1.5707963267949 -0.852106499830378 -0.102417256192126" />
    <parent
      link="link_wrist" />
    <child
      link="link_non_motor_support" />
    <axis
      xyz="0 0 -1" />
    <limit
      lower="-1.4"
      upper="1.4"
      effort="0"
      velocity="10" />
<mimic joint="joint_wrist_motor_gear" multiplier="-1.2"/>
  </joint>


<!--Transmissions-->

<transmission name="trans_joint_base_waist">
  <type>transmission_interface/SimpleTransmission</type>
  <joint name="joint_base_waist">
    <hardwareInterface>PositionJointInterface</hardwareInterface>
  </joint>
  <actuator name="actuator_joint_base_waist">
    <hardwareInterface>PositionJointInterface</hardwareInterface>
  </actuator>
</transmission>

<transmission name="trans_joint_waist_arm01">
  <type>transmission_interface/SimpleTransmission</type>
  <joint name="joint_waist_arm01">
    <hardwareInterface>PositionJointInterface</hardwareInterface>
  </joint>
  <actuator name="actuator_joint_waist_arm01">
    <hardwareInterface>PositionJointInterface</hardwareInterface>
  </actuator>
</transmission>

<transmission name="trans_joint_arm01_arm02">
  <type>transmission_interface/SimpleTransmission</type>
  <joint name="joint_arm01_arm02">
    <hardwareInterface>PositionJointInterface</hardwareInterface>
  </joint>
  <actuator name="actuator_joint_arm01_arm02">
    <hardwareInterface>PositionJointInterface</hardwareInterface>
  </actuator>
</transmission>

<transmission name="trans_joint_arm02_arm03">
  <type>transmission_interface/SimpleTransmission</type>
  <joint name="joint_arm02_arm03">
    <hardwareInterface>PositionJointInterface</hardwareInterface>
  </joint>
  <actuator name="actuator_joint_arm02_arm03">
    <hardwareInterface>PositionJointInterface</hardwareInterface>
  </actuator>
</transmission>

<transmission name="trans_joint_arm03_wrist">
  <type>transmission_interface/SimpleTransmission</type>
  <joint name="joint_arm03_wrist">
    <hardwareInterface>PositionJointInterface</hardwareInterface>
  </joint>
  <actuator name="actuator_joint_arm03_wrist">
    <hardwareInterface>PositionJointInterface</hardwareInterface>
  </actuator>
</transmission>

<transmission name="trans_joint_wrist_motor_gear">
  <type>transmission_interface/SimpleTransmission</type>
  <joint name="joint_wrist_motor_gear">
    <hardwareInterface>PositionJointInterface</hardwareInterface>
  </joint>
  <actuator name="actuator_joint_wrist_motor_gear">
    <hardwareInterface>PositionJointInterface</hardwareInterface>
  </actuator>
</transmission>
<!--End of transmissions-->

<gazebo>
  <plugin name="control" filename="libgazebo_ros_control.so">
    <robotNamespace>/</robotNamespace>
  </plugin>
</gazebo>
<gazebo reference="base_link">
  <selfCollide>true</selfCollide>
</gazebo>

<gazebo reference="link_waist">
  <selfCollide>true</selfCollide>
</gazebo>

<gazebo reference="link_arm01">
  <selfCollide>true</selfCollide>
</gazebo>

<gazebo reference="link_arm02">
  <selfCollide>true</selfCollide>
</gazebo>

<gazebo reference="link_arm03">
  <selfCollide>true</selfCollide>
</gazebo>

<gazebo reference="link_wrist">
  <selfCollide>true</selfCollide>
</gazebo>

<gazebo reference="link_servo">
  <selfCollide>true</selfCollide>
</gazebo>

<gazebo reference="link_motor_gear">
  <selfCollide>true</selfCollide>
</gazebo>

<gazebo reference="link_motor_finger">
  <selfCollide>true</selfCollide>
</gazebo>

<gazebo reference="link_non_motor_gear">
  <selfCollide>true</selfCollide>
</gazebo>

<gazebo reference="link_non_motor_finger">
  <selfCollide>true</selfCollide>
</gazebo>

<gazebo reference="link_motor_support">
  <selfCollide>true</selfCollide>
</gazebo>

<gazebo reference="link_non_motor_support">
  <selfCollide>true</selfCollide>
</gazebo>



</robot>